<robot name="demo04_base_footprint">
    
    <material name="yellow">
        <color rgba="0.8 0.8 0.0 0.5"/>
    </material>

    <material name="red">
        <color rgba="0.9 0.0 0.0 0.5"/>
    </material>

    <link name="base_footprint">
        <visual>
            <geometry>
                <geometry>
                    <sphere radius="0.001"/>
                </geometry>
            </geometry>
        </visual>
    </link>

    <link name="base_link">
        <visual>
            <geometry>
                <box size="0.5 0.3 0.1"/>
            </geometry>
            <material name = "yellow" />
        </visual>
    </link>

    <link name="camera">
        <visual>
            <geometry>
                <box size="0.02 0.05 0.05"/>
            </geometry>
            <material name="red"/>
        </visual>
    </link>

    <joint name="base_link2base_footprint" type="fixed">
        <parent link="base_footprint"/>
        <child link="base_link"/>
        <origin xyz="0.0 0.0 0.05"/>
    </joint>

    <joint name="camera2base_link" type="continuous">
        <parent link="base_link"/>
        <child link="camera"/>
        <origin xyz="0.05 0.0 0.075"/>
        <axis xyz="0.0 0.0 0.0"/>
    </joint>

    <link name="left_front_wheel">
        <visual>
            <geometry>
                <cylinder radius="0.025" length="0.02"/>
            </geometry>
            <material name="red"/>
        </visual>
    </link>

    <joint name="left_front_wheel2base_link" type="continuous">
        <parent link="base_link"/>
        <child link="left_front_wheel"/>
        
    </joint>
    
</robot>