<robot name="demo03_joint">
    
    <material name="yellow">
        <color rgba="0.8 0.8 0.0 0.5"/>
    </material>

    <material name="red">
        <color rgba="0.9 0.0 0.0 0.5"/>
    </material>

    <link name="base_link">
        <visual>
            <geometry>
                <box size="0.5 0.3 0.1"/>
            </geometry>
            <material name = "yellow" />
        </visual>
    </link>

    <link name="camera">
        <visual>
            <geometry>
                <box size="0.02 0.05 0.05"/>
            </geometry>
            <material name="red"/>
        </visual>
    </link>

    <joint name="camera2base_link" type="continuous">
        <parent link="base_link"/>
        <child link="camera"/>
        <origin xyz="0.2 0.0 0.075"/>
        <axis xyz="0.0 0.0 1"/>
    </joint>
    
</robot>